from datetime import datetime, timedelta
from jose import JWTError, jwt
from passlib.context import CryptContext
from fastapi import Depends, HTTPException
from fastapi.security import OAuth2PasswordBearer
from sqlalchemy.orm import Session

from app.core.config import settings
from app.core.database import get_db
from app.models import User

pwd_context = CryptContext(schemes=["bcrypt"], deprecated="auto")

oauth2_scheme = OAuth2PasswordBearer(tokenUrl="/api/v1/auth/login")


def hash_password(password: str) -> str:
    return pwd_context.hash(password)

def verify_password(plain_password: str, hashed_password: str) -> bool:
    return pwd_context.verify(plain_password, hashed_password)

def create_access_token(data: dict, expires_delta: timedelta = timedelta(minutes=30)):
    to_encode = data.copy()
    expire = datetime.utcnow() + expires_delta
    to_encode.update({"exp": expire})
    return jwt.encode(to_encode, settings.JWT_SECRET_KEY, algorithm="HS256")

def create_refresh_token(data: dict, expires_delta: timedelta = timedelta(days=7)):
    to_encode = data.copy()
    expire = datetime.utcnow() + expires_delta
    to_encode.update({"exp": expire})
    return jwt.encode(to_encode, settings.JWT_REFRESH_SECRET_KEY, algorithm="HS256")

def get_current_user(token: str = Depends(oauth2_scheme), db: Session = Depends(get_db)) -> User:
    credentials_exception = HTTPException(
        status_code=401,
        detail="No se pudo validar las credenciales",
        headers={"WWW-Authenticate": "Bearer"},
    )
    try:
        payload = jwt.decode(token, settings.JWT_SECRET_KEY, algorithms=["HS256"])
        user_id: str = payload.get("sub")
        if user_id is None:
            raise credentials_exception
    except JWTError:
        raise credentials_exception

    user = db.query(User).filter(User.id == user_id, User.is_active == True).first()
    if user is None:
        raise credentials_exception
    return user
